Exception: {'message': 'Task exception was never retrieved', 'exception': OSError(113, "Connect call failed ('207.53.234.101', 443)"), 'future': <Task finished name='Task-5' coro=<Itl._attach_stream() done, defined at /home/sen/.local/lib/python3.11/site-packages/itllib/itl.py:564> exception=OSError(113, "Connect call failed ('207.53.234.101', 443)") created at /usr/lib/python3.11/asyncio/tasks.py:384>, 'source_traceback': [<FrameSummary file /usr/lib/python3.11/threading.py, line 1002 in _bootstrap>, <FrameSummary file /usr/lib/python3.11/threading.py, line 1045 in _bootstrap_inner>, <FrameSummary file /usr/lib/python3.11/threading.py, line 982 in run>, <FrameSummary file /home/sen/.local/lib/python3.11/site-packages/itllib/itl.py, line 705 in _handle_connections_in_thread>, <FrameSummary file /usr/lib/python3.11/asyncio/base_events.py, line 641 in run_until_complete>, <FrameSummary file /usr/lib/python3.11/asyncio/base_events.py, line 608 in run_forever>, <FrameSummary file /usr/lib/python3.11/asyncio/base_events.py, line 1928 in _run_once>, <FrameSummary file /usr/lib/python3.11/asyncio/events.py, line 84 in _run>, <FrameSummary file /home/sen/.local/lib/python3.11/site-packages/itllib/itl.py, line 763 in _start_routine>, <FrameSummary file /home/sen/.local/lib/python3.11/site-packages/itllib/itl.py, line 301 in <lambda>>, <FrameSummary file /home/sen/.local/lib/python3.11/site-packages/itllib/itl.py, line 319 in _schedule_stream_task_unsafe>, <FrameSummary file /usr/lib/python3.11/asyncio/tasks.py, line 384 in create_task>]}

